Workbook

Sheet 1월
C1: 월말 회계 보고서 | F1: (사)건설경제연구원_경영관리실
A2: 1. 1월 계약현황 및 매출현황
A3: 1)계약현황
A4: ①총계약건수: | B4: =SUM(C7:C14) -> 0
A5: ②총계약금액: | B5: =SUM(A8,A10,A12,A14) -> 0
A6: 사업부 | B6: 용역종류 | C6: 건수 | D6: 계약금액 | E6: 업체명 | F6: 용역명
A7: 개발사업부
A8: =SUM(D7:D8) -> 0
A9: 건설사업부
A10: =SUM(D9:D10) -> 0
A11: 학술사업부
A12: =SUM(D11:D12) -> 0
A13: 외주용역
A14: =SUM(D13:D14) -> 0
A15: 2)매출현황
A16: ①총매출건수: | B16: =SUM(C19:C29) -> 0
A17: ②총매출금액: | B17: =SUM(A22,A25,A27,A29) -> 0
A18: 사업부 | B18: 용역종류 | C18: 건수 | D18: 매출금액 | E18: 업체명 | F18: 용역명
A19: 개발사업부
A22: =SUM(D19:D22) -> 0
A23: 건설사업부
A25: =SUM(D23:D25) -> 0
A26: 학술사업부
A27: =SUM(D26:D27) -> 0
A28: 외주용역
A29: =SUM(D28:D29) -> 0
A30: 2. 1월 순이익현황
A31: 총매출금액 | B31: 1월 수금액 | C31: 경비 | D31: 매출대비 순이익 | E31: 수금대비 순이익 | F31: 총수금액 | G31: =SUM(G33:G37) -> 0
F32: 사업부서 수금액 | G32: =SUM(G33:G36) -> 0
A33: =B17 -> 0 | B33: =G31 -> 0 | D33: =A33-C33 -> 0 | E33: =B33-C33 -> 0 | F33: 개발사업부
F34: 건설사업부
F35: 학술사업부
F36: 외주용역 | G36: 0
F37: 기타 | G37: 0

Sheet 2월
C1: 월말 회계 보고서 | F1: (사)건설경제연구원_경영관리실
A2: 1. 2월 계약현황 및 매출현황
A3: 1)계약현황
A4: ①총계약건수: | B4: =SUM(C7:C17) -> 0
A5: ②총계약금액: | B5: =SUM(A8,A13,A15,A17) -> 0
A6: 사업부 | B6: 용역종류 | C6: 건수 | D6: 계약금액 | E6: 업체명 | F6: 용역명
A7: 개발사업부
A8: =SUM(D7:D8) -> 0
A9: 건설사업부
A13: =SUM(D9:D13) -> 0
A14: 학술사업부
A15: =SUM(D14:D15) -> 0
A16: 외주용역
A17: =SUM(D16:D17) -> 0
A18: 2)매출현황
A19: ①총매출건수: | B19: =SUM(C22:C31) -> 0
A20: ②총매출금액: | B20: =SUM(A23,A26,A29,A31) -> 0
A21: 사업부 | B21: 용역종류 | C21: 건수 | D21: 매출금액 | E21: 업체명 | F21: 용역명
A22: 개발사업부
A23: =SUM(D22:D23) -> 0
A24: 건설사업부
A26: =SUM(D24:D26) -> 0
A27: 학술사업부
A29: =SUM(D27:D29) -> 0
A30: 외주용역
A31: =SUM(D30:D31) -> 0
A32: 2. 2월 순이익현황
A33: 총매출금액 | B33: 2월 수금액 | C33: 경비 | D33: 매출대비 순이익 | E33: 수금대비 순이익 | F33: 총수금액 | G33: =SUM(G35:G39) -> 0
F34: 사업부서 수금액 | G34: =SUM(G35:G38) -> 0
A35: =B20 -> 0 | B35: =G33 -> 0 | D35: =A35-C35 -> 0 | E35: =B35-C35 -> 0 | F35: 개발사업부
F36: 건설사업부
F37: 학술사업부
F38: 외주용역
F39: 기타 | G39: 0

Sheet 3월
C1: 월말 회계 보고서 | F1: (사)건설경제연구원_경영관리실
A2: 1. 3월 계약현황 및 매출현황
A3: 1)계약현황
A4: ①총계약건수: | B4: =SUM(C7:C23) -> 0
A5: ②총계약금액: | B5: =SUM(A8,A18,A21,A23) -> 0
A6: 사업부 | B6: 용역종류 | C6: 건수 | D6: 계약금액 | E6: 업체명 | F6: 용역명
A7: 개발사업부
A8: =SUM(D7:D8) -> 0
A9: 건설사업부
A18: =SUM(D9:D18) -> 0
A19: 학술사업부
A21: =SUM(D19:D21) -> 0
A22: 외주용역
A23: =SUM(D22:D23) -> 0
A24: 2)매출현황
A25: ①총매출건수: | B25: =SUM(C28:C45) -> 0
A26: ②총매출금액: | B26: =SUM(A29,A38,A41,A45) -> 0
A27: 사업부 | B27: 용역종류 | C27: 건수 | D27: 매출금액 | E27: 업체명 | F27: 용역명
A28: 개발사업부
A29: =SUM(D28:D29) -> 0
A30: 건설사업부
A38: =SUM(D30:D38) -> 0
A39: 학술사업부
A41: =SUM(D39:D41) -> 0
A42: 외주용역
A45: =SUM(D42:D45) -> 0
A46: 2. 3월 순이익현황
A47: 총매출금액 | B47: 3월 수금액 | C47: 경비 | D47: 매출대비 순이익 | E47: 수금대비 순이익 | F47: 총수금액 | G47: =SUM(G49:G53) -> 0
F48: 사업부서 수금액 (기타 제외) | G48: =SUM(G49:G52) -> 0
A49: =B26 -> 0 | B49: =G47 -> 0 | D49: =A49-C49 -> 0 | E49: =B49-C49 -> 0 | F49: 개발사업부
F50: 건설사업부
F51: 학술사업부
F52: 외주용역
F53: 기타

Sheet 4월
C1: 월말 회계 보고서 | F1: (사)건설경제연구원_경영관리실
A2: 1. 4월 계약현황 및 매출현황
A3: 1)계약현황
A4: ①총계약건수: | B4: =SUM(C7:C18) -> 0
A5: ②총계약금액: | B5: =SUM(A9,A14,A16,A18) -> 0
A6: 사업부 | B6: 용역종류 | C6: 건수 | D6: 계약금액 | E6: 업체명 | F6: 용역명
A7: 개발사업부
A9: =SUM(D7:D9) -> 0
A10: 건설사업부
A14: =SUM(D10:D14) -> 0
A15: 학술사업부
A16: =SUM(D15:D16) -> 0
A17: 외주용역
A18: =SUM(D17:D18) -> 0
A19: 2)매출현황
A20: ①총매출건수: | B20: =SUM(C23:C37) -> 0
A21: ②총매출금액: | B21: =SUM(A24,A33,A35,A37) -> 0
A22: 사업부 | B22: 용역종류 | C22: 건수 | D22: 매출금액 | E22: 업체명 | F22: 용역명
A23: 개발사업부
A24: =SUM(D23:D24) -> 0
A25: 건설사업부
A33: =SUM(D25:D33) -> 0
A34: 학술사업부
A35: =SUM(D34:D35) -> 0
A36: 외주용역
A37: =SUM(D36:D37) -> 0
A38: 2. 4월 순이익현황
A39: 총매출금액 | B39: 4월 수금액 | C39: 경비 | D39: 매출대비 순이익 | E39: 수금대비 순이익 | F39: 총수금액 | G39: =SUM(G41:G45) -> 0
F40: 사업부서 수금액 | G40: =SUM(G41:G44) -> 0
A41: =B21 -> 0 | B41: =G39 -> 0 | D41: =A41-C41 -> 0 | E41: =B41-C41 -> 0 | F41: 개발사업부
F42: 건설사업부
F43: 학술사업부
F44: 외주용역
F45: 기타

Sheet 5월
C1: 월말 회계 보고서 | F1: (사)건설경제연구원_경영관리실
A2: 1. 5월 계약현황 및 매출현황
A3: 1)계약현황
A4: ①총계약건수: | B4: =SUM(C7:C17) -> 0
A5: ②총계약금액: | B5: =SUM(A8,A11,A13,A17) -> 0
A6: 사업부 | B6: 용역종류 | C6: 건수 | D6: 계약금액 | E6: 업체명 | F6: 용역명
A7: 개발사업부
A8: =SUM(D7:D8) -> 0
A9: 건설사업부
A11: =SUM(D9:D11) -> 0
A12: 학술사업부
A13: =SUM(D12:D13) -> 0
A14: 외주용역
A17: =SUM(D14:D17) -> 0
A18: 2)매출현황
A19: ①총매출건수: | B19: =SUM(C22:C35) -> 0
A20: ②총매출금액: | B20: =SUM(A23,A29,A31,A35) -> 0
A21: 사업부 | B21: 용역종류 | C21: 건수 | D21: 매출금액 | E21: 업체명 | F21: 용역명
A22: 개발사업부
A23: =SUM(D22:D23) -> 0
A24: 건설사업부
A29: =SUM(D24:D29) -> 0
A30: 학술사업부
A31: =SUM(D30:D31) -> 0
A32: 외주용역
A35: =SUM(D32:D35) -> 0
A36: 2. 5월 순이익현황
A37: 총매출금액 | B37: 5월 수금액 | C37: 경비 | D37: 매출대비 순이익 | E37: 수금대비 순이익 | F37: 총수금액 | G37: =SUM(G39:G43) -> 0
F38: 사업부서 수금액 | G38: =SUM(G39:G42) -> 0
A39: =B20 -> 0 | B39: =G37 -> 0 | D39: =A39-C39 -> 0 | E39: =B39-C39 -> 0 | F39: 개발사업부
F40: 건설사업부
F41: 학술사업부
F42: 외주용역
F43: 기타

Sheet 6월
C1: 월말 회계 보고서 | F1: (사)건설경제연구원_경영관리실
A2: 1. 6월 계약현황 및 매출현황
A3: 1)계약현황
A4: ①총계약건수: | B4: =SUM(C7:C21) -> 0
A5: ②총계약금액: | B5: =SUM(A8,A16,A18,A21) -> 0
A6: 사업부 | B6: 용역종류 | C6: 건수 | D6: 계약금액 | E6: 업체명 | F6: 용역명
A7: 개발사업부
A8: =SUM(D7:D8) -> 0
A9: 건설사업부
A16: =SUM(D9:D16) -> 0
A17: 학술사업부
A18: =SUM(D17:D18) -> 0
A19: 외주용역
A21: =SUM(D19:D21) -> 0
A22: 2)매출현황
A23: ①총매출건수: | B23: =SUM(C26:C36) -> 0
A24: ②총매출금액: | B24: =SUM(A27,A30,A32,A36) -> 0
A25: 사업부 | B25: 용역종류 | C25: 건수 | D25: 매출금액 | E25: 업체명 | F25: 용역명
A26: 개발사업부
A27: =SUM(D26:D27) -> 0
A28: 건설사업부
A30: =SUM(D28:D30) -> 0
A31: 학술사업부
A32: =SUM(D31:D32) -> 0
A33: 외주용역
A36: =SUM(D33:D36) -> 0
A37: 2. 6월 순이익현황
A38: 총매출금액 | B38: 6월 수금액 | C38: 경비 | D38: 매출대비 순이익 | E38: 수금대비 순이익 | F38: 총수금액 | G38: =SUM(G40:G44) -> 0
F39: 사업부서 수금액 | G39: =SUM(G40:G43) -> 0
A40: =B24 -> 0 | B40: =G38 -> 0 | D40: =A40-C40 -> 0 | E40: =B40-C40 -> 0 | F40: 개발사업부
F41: 건설사업부
F42: 학술사업부
F43: 외주용역
F44: 경영관리실_예금결산이자

Sheet 7월
C1: 월말 회계 보고서 | F1: (사)건설경제연구원_경영관리실
A2: 1. 7월 계약현황 및 매출현황
A3: 1)계약현황
A4: ①총계약건수: | B4: =SUM(C7:C21) -> 0
A5: ②총계약금액: | B5: =SUM(A8,A16,A18,A21) -> 0
A6: 사업부 | B6: 용역종류 | C6: 건수 | D6: 계약금액 | E6: 업체명 | F6: 용역명
A7: 개발사업부
A8: =SUM(D7:D8) -> 0
A9: 건설사업부
A16: =SUM(D9:D16) -> 0
A17: 학술사업부
A18: =SUM(D17:D18) -> 0
A19: 외주용역
A21: =SUM(D19:D21) -> 0
A22: 2)매출현황
A23: ①총매출건수: | B23: =SUM(C26:C40) -> 0
A24: ②총매출금액: | B24: =SUM(A27,A34,A36,A40) -> 0
A25: 사업부 | B25: 용역종류 | C25: 건수 | D25: 매출금액 | E25: 업체명 | F25: 용역명
A26: 개발사업부
A27: =SUM(D26:D27) -> 0
A28: 건설사업부
A34: =SUM(D28:D34) -> 0
A35: 학술사업부
A36: =SUM(D35:D36) -> 0
A37: 외주용역
A40: =SUM(D37:D40) -> 0
A41: 2. 7월 순이익현황
A42: 총매출금액 | B42: 7월 수금액 | C42: 경비 | D42: 매출대비 순이익 | E42: 수금대비 순이익 | F42: 총수금액 | G42: =SUM(G44:G48) -> 0
F43: 사업부서 수금액 | G43: =SUM(G44:G47) -> 0
A44: =B24 -> 0 | B44: =G42 -> 0 | D44: =A44-C44 -> 0 | E44: =B44-C44 -> 0 | F44: 개발사업부
F45: 건설사업부
F46: 학술사업부
F47: 외주용역
F48: 경영관리실, 기타

Sheet 8월
C1: 월말 회계 보고서 | F1: (사)건설경제연구원_경영관리실
A2: 1. 8월 계약현황 및 매출현황
A3: 1)계약현황
A4: ①총계약건수: | B4: =SUM(C7:C16) -> 0
A5: ②총계약금액: | B5: =SUM(A8,A11,A13,A16) -> 0
A6: 사업부 | B6: 용역종류 | C6: 건수 | D6: 계약금액 | E6: 업체명 | F6: 용역명
A7: 개발사업부
A8: =SUM(D7:D8) -> 0
A9: 건설사업부
A11: =SUM(D9:D11) -> 0
A12: 학술사업부
A13: =SUM(D12:D13) -> 0
A14: 외주용역
A16: =SUM(D14:D16) -> 0
A17: 2)매출현황
A18: ①총매출건수: | B18: =SUM(C21:C32) -> 0
A19: ②총매출금액: | B19: =SUM(A22,A27,A29,A32) -> 0
A20: 사업부 | B20: 용역종류 | C20: 건수 | D20: 매출금액 | E20: 업체명 | F20: 용역명
A21: 개발사업부
A22: =SUM(D21:D22) -> 0
A23: 건설사업부
A27: =SUM(D23:D27) -> 0
A28: 학술사업부
A29: =SUM(D28:D29) -> 0
A30: 외주용역
A32: =SUM(D30:D32) -> 0
A33: 2. 8월 순이익현황
A34: 총매출금액 | B34: 8월 수금액 | C34: 경비 | D34: 매출대비 순이익 | E34: 수금대비 순이익 | F34: 총수금액 | G34: =SUM(G36:G39) -> 0
F35: 사업부서 수금액 | G35: =SUM(G36:G39) -> 0
A36: =B19 -> 0 | B36: =G34 -> 0 | D36: =A36-C36 -> 0 | E36: =B36-C36 -> 0 | F36: 개발사업부
F37: 건설사업부
F38: 학술사업부
F39: 외주용역

Sheet 9월
C1: 월말 회계 보고서 | F1: (사)건설경제연구원_경영관리실
A2: 1. 9월 계약현황 및 매출현황
A3: 1)계약현황
A4: ①총계약건수: | B4: =SUM(C7:C25) -> 0
A5: ②총계약금액: | B5: =SUM(A9,A20,A22,A25) -> 0
A6: 사업부 | B6: 용역종류 | C6: 건수 | D6: 계약금액 | E6: 업체명 | F6: 용역명
A7: 개발사업부
A9: =SUM(D7:D9) -> 0
A10: 건설사업부
A20: =SUM(D10:D20) -> 0
A21: 학술사업부
A22: =SUM(D21:D22) -> 0
A23: 외주용역
A25: =SUM(D23:D25) -> 0
A26: 2)매출현황
A27: ①총매출건수: | B27: =SUM(C30:C50) -> 0
A28: ②총매출금액: | B28: =SUM(A32,A44,A47,A50) -> 0
A29: 사업부 | B29: 용역종류 | C29: 건수 | D29: 매출금액 | E29: 업체명 | F29: 용역명
A30: 개발사업부
A32: =SUM(D30:D32) -> 0
A33: 건설사업부
A44: =SUM(D33:D44) -> 0
A45: 학술사업부
A47: =SUM(D45:D47) -> 0
A48: 외주용역
A50: =SUM(D48:D50) -> 0
A51: 2. 9월 순이익현황
A52: 총매출금액 | B52: 9월 수금액 | C52: 경비 | D52: 매출대비 순이익 | E52: 수금대비 순이익 | F52: 총수금액 | G52: =SUM(G54:G59) -> 0
F53: 사업부서 수금액 | G53: =SUM(G54:G57) -> 0
A54: =B28 -> 0 | B54: =G52 -> 0 | D54: =A54-C54 -> 0 | E54: =B54-C54 -> 0 | F54: 개발사업부
F55: 건설사업부
F56: 학술사업부
F57: 외주용역
F58: 경영관리실
F59: 기타

Sheet 10월
C1: 월말 회계 보고서 | F1: (사)건설경제연구원_경영관리실
A2: 1. 10월 계약현황 및 매출현황
A3: 1)계약현황
A4: ①총계약건수: | B4: =SUM(C7:C22) -> 0
A5: ②총계약금액: | B5: =SUM(A9,A18,A20,A22) -> 0
A6: 사업부 | B6: 용역종류 | C6: 건수 | D6: 계약금액 | E6: 업체명 | F6: 용역명
A7: 개발사업부
A9: =SUM(D7:D9) -> 0
A10: 건설사업부
A18: =SUM(D10:D18) -> 0
A19: 학술사업부
A20: =SUM(D19:D20) -> 0
A21: 외주용역
A22: =SUM(D21:D22) -> 0
A23: 2)매출현황
A24: ①총매출건수: | B24: =SUM(C27:C41) -> 0
A25: ②총매출금액: | B25: =SUM(A28,A37,A39,A41) -> 0
A26: 사업부 | B26: 용역종류 | C26: 건수 | D26: 매출금액 | E26: 업체명 | F26: 용역명
A27: 개발사업부
A28: =SUM(D27:D28) -> 0
A29: 건설사업부
A37: =SUM(D29:D37) -> 0
A38: 학술사업부
A39: =SUM(D38:D39) -> 0
A40: 외주용역
A41: =SUM(D40:D41) -> 0
A42: 2. 10월 순이익현황
A43: 총매출금액 | B43: 10월 수금액 | C43: 경비 | D43: 매출대비 순이익 | E43: 수금대비 순이익 | F43: 총수금액 | G43: =SUM(G45:G49) -> 0
F44: 사업부서 수금액 | G44: =SUM(G45:G48) -> 0
A45: =B25 -> 0 | B45: =G43 -> 0 | D45: =A45-C45 -> 0 | E45: =B45-C45 -> 0 | F45: 개발사업부
F46: 건설사업부
F47: 학술사업부
F48: 외주용역
F49: 경영관리실

Sheet 11월
C1: 월말 회계 보고서 | F1: (사)건설경제연구원_경영관리실
A2: 1. 11월 계약현황 및 매출현황
A3: 1)계약현황
A4: ①총계약건수: | B4: =SUM(C7:C15) -> 0
A5: ②총계약금액: | B5: =SUM(A8,A11,A13,A15) -> 0
A6: 사업부 | B6: 용역종류 | C6: 건수 | D6: 계약금액 | E6: 업체명 | F6: 용역명
A7: 개발사업부
A8: =SUM(D7:D8) -> 0
A9: 건설사업부
A11: =SUM(D9:D11) -> 0
A12: 학술사업부
A13: =SUM(D12:D13) -> 0
A14: 외주용역
A15: =SUM(D14:D15) -> 0
A16: 2)매출현황
A17: ①총매출건수: | B17: =SUM(C20:C32) -> 0
A18: ②총매출금액: | B18: =SUM(A21,A28,A30,A32) -> 0
A19: 사업부 | B19: 용역종류 | C19: 건수 | D19: 매출금액 | E19: 업체명 | F19: 용역명
A20: 개발사업부
A21: =SUM(D20:D21) -> 0
A22: 건설사업부
A28: =SUM(D22:D28) -> 0
A29: 학술사업부
A30: =SUM(D29:D30) -> 0
A31: 외주용역
A32: =SUM(D31:D32) -> 0
A33: 2. 11월 순이익현황
A34: 총매출금액 | B34: 11월 수금액 | C34: 경비 | D34: 매출대비 순이익 | E34: 수금대비 순이익 | F34: 총수금액 | G34: =SUM(G36:G40) -> 0
F35: 사업부서 수금액 | G35: =SUM(G36:G39) -> 0
A36: =B18 -> 0 | B36: =G34 -> 0 | D36: =A36-C36 -> 0 | E36: =B36-C36 -> 0 | F36: 개발사업부
F37: 건설사업부
F38: 학술사업부
F39: 외주용역
F40: 기타

Sheet 12월
C1: 월말 회계 보고서 | F1: (사)건설경제연구원_경영관리실
A2: 1. 12월 계약현황 및 매출현황
A3: 1)계약현황
A4: ①총계약건수: | B4: =SUM(C7:C15) -> 0
A5: ②총계약금액: | B5: =SUM(A8,A11,A13,A15) -> 0
A6: 사업부 | B6: 용역종류 | C6: 건수 | D6: 계약금액 | E6: 업체명 | F6: 용역명
A7: 개발사업부
A8: =SUM(D7:D8) -> 0
A9: 건설사업부
A11: =SUM(D9:D11) -> 0
A12: 학술사업부
A13: =SUM(D12:D13) -> 0
A14: 외주용역
A15: =SUM(D14:D15) -> 0
A16: 2)매출현황
A17: ①총매출건수: | B17: =SUM(C20:C32) -> 0
A18: ②총매출금액: | B18: =SUM(A21,A28,A30,A32) -> 0
A19: 사업부 | B19: 용역종류 | C19: 건수 | D19: 매출금액 | E19: 업체명 | F19: 용역명
A20: 개발사업부
A21: =SUM(D20:D21) -> 0
A22: 건설사업부
A28: =SUM(D22:D28) -> 0
A29: 학술사업부
A30: =SUM(D29:D30) -> 0
A31: 외주용역
A32: =SUM(D31:D32) -> 0
A33: 2. 12월 순이익현황
A34: 총매출금액 | B34: 12월 수금액 | C34: 경비 | D34: 매출대비 순이익 | E34: 수금대비 순이익 | F34: 총수금액 | G34: =SUM(G36:G40) -> 0
F35: 사업부서 수금액 | G35: =SUM(G36:G39) -> 0
A36: =B18 -> 0 | B36: =G34 -> 0 | D36: =A36-C36 -> 0 | E36: =B36-C36 -> 0 | F36: 개발사업부
F37: 건설사업부
F38: 학술사업부
F39: 외주용역
F40: 기타

Sheet 총매출현황
A1: 3. 2026년 계약현황, 매출현황
A2: 1)계약현황
A3: 계약
A4: 월 | B4: 건설사업부 | D4: 학술사업부 | F4: 개발사업부 | H4: 외주용역 | J4: 합계 | L4: 비고
B5: 건수 | C5: 금액 | D5: 건수 | E5: 금액 | F5: 건수 | G5: 금액 | H5: 건수 | I5: 금액 | J5: 총건수 | K5: 총금액
A6: 1월 | B6: =SUM('1월'!C9:C10) -> 0 | C6: ='1월'!A10 -> 0 | D6: =SUM('1월'!C11:C12) -> 0 | E6: ='1월'!A12 -> 0 | F6: =SUM('1월'!C7:C8) -> 0 | G6: ='1월'!A8 -> 0 | H6: =SUM('1월'!C13:C14) -> 0 | I6: ='1월'!A14 -> 0 | J6: =B6+D6+F6+H6 -> 0 | K6: =C6+E6+G6+I6 -> 0
A7: 2월 | B7: =SUM('2월'!C9:C13) -> 0 | C7: ='2월'!A13 -> 0 | D7: =SUM('2월'!C14:C15) -> 0 | E7: ='2월'!A15 -> 0 | F7: =SUM('2월'!C7:C8) -> 0 | G7: ='2월'!A8 -> 0 | H7: =SUM('2월'!C16:C17) -> 0 | I7: ='2월'!A17 -> 0 | J7: =B7+D7+F7+H7 -> 0 | K7: =C7+E7+G7+I7 -> 0
A8: 3월 | B8: =SUM('3월'!C9:C18) -> 0 | C8: ='3월'!A18 -> 0 | D8: =SUM('3월'!C19:C21) -> 0 | E8: ='3월'!A21 -> 0 | F8: =SUM('3월'!C7:C8) -> 0 | G8: ='3월'!A8 -> 0 | H8: =SUM('3월'!C7:C8) -> 0 | I8: ='3월'!A23 -> 0 | J8: =B8+D8+F8+H8 -> 0 | K8: =C8+E8+G8+I8 -> 0
A9: 4월 | B9: =SUM('4월'!C25:C33) -> 0 | C9: ='4월'!A14 -> 0 | D9: =SUM('4월'!C15:C16) -> 0 | E9: ='4월'!A16 -> 0 | F9: =SUM('4월'!C7:C9) -> 0 | G9: ='4월'!A9 -> 0 | H9: =SUM('4월'!C17:C18) -> 0 | I9: ='4월'!A18 -> 0 | J9: =B9+D9+F9+H9 -> 0 | K9: =C9+E9+G9+I9 -> 0
A10: 5월 | B10: =SUM('5월'!C9:C11) -> 0 | C10: ='5월'!A11 -> 0 | D10: =SUM('5월'!C12:C13) -> 0 | E10: ='5월'!A13 -> 0 | F10: =SUM('5월'!C7:C8) -> 0 | G10: ='5월'!A8 -> 0 | H10: =SUM('5월'!C7:C8) -> 0 | I10: ='5월'!A17 -> 0 | J10: =B10+D10+F10+H10 -> 0 | K10: =C10+E10+G10+I10 -> 0
A11: 6월 | B11: =SUM('6월'!C9:C16) -> 0 | C11: ='6월'!A16 -> 0 | D11: =SUM('6월'!C17:C18) -> 0 | E11: ='6월'!A18 -> 0 | F11: =SUM('6월'!C7:C8) -> 0 | G11: ='6월'!A8 -> 0 | H11: =SUM('6월'!C7:C8) -> 0 | I11: ='6월'!A21 -> 0 | J11: =B11+D11+F11+H11 -> 0 | K11: =C11+E11+G11+I11 -> 0
A12: 7월 | B12: =SUM('7월'!C9:C16) -> 0 | C12: ='7월'!A16 -> 0 | D12: =SUM('7월'!C17:C18) -> 0 | E12: ='7월'!A18 -> 0 | F12: =SUM('7월'!C7:C8) -> 0 | G12: ='7월'!A8 -> 0 | H12: =SUM('7월'!C19:C21) -> 0 | I12: ='7월'!A21 -> 0 | J12: =B12+D12+F12+H12 -> 0 | K12: =C12+E12+G12+I12 -> 0
A13: 8월 | B13: =SUM('8월'!C9:C11) -> 0 | C13: ='8월'!A11 -> 0 | D13: =SUM('8월'!C12:C13) -> 0 | E13: ='8월'!A13 -> 0 | F13: =SUM('8월'!C7:C8) -> 0 | G13: ='8월'!A8 -> 0 | H13: =SUM('8월'!C14:C16) -> 0 | I13: ='8월'!A16 -> 0 | J13: =B13+D13+F13+H13 -> 0 | K13: =C13+E13+G13+I13 -> 0
A14: 9월 | B14: =SUM('9월'!C10:C20) -> 0 | C14: ='9월'!A20 -> 0 | D14: =SUM('9월'!C21:C22) -> 0 | E14: ='9월'!A22 -> 0 | F14: =SUM('9월'!C7:C9) -> 0 | G14: ='9월'!A9 -> 0 | H14: =SUM('9월'!C23:C25) -> 0 | I14: ='9월'!A25 -> 0 | J14: =B14+D14+F14+H14 -> 0 | K14: =C14+E14+G14+I14 -> 0
A15: 10월 | B15: =SUM('10월'!C10:C18) -> 0 | C15: ='10월'!A18 -> 0 | D15: =SUM('10월'!C19:C20) -> 0 | E15: ='10월'!A20 -> 0 | F15: =SUM('10월'!C7:C9) -> 0 | G15: ='10월'!A9 -> 0 | H15: =SUM('10월'!C21:C22) -> 0 | I15: ='10월'!A22 -> 0 | J15: =B15+D15+F15+H15 -> 0 | K15: =C15+E15+G15+I15 -> 0
A16: 11월 | C16: ='11월'!A11 -> 0 | E16: ='11월'!A13 -> 0 | G16: ='11월'!A8 -> 0 | I16: ='11월'!A15 -> 0 | J16: =B16+D16+F16+H16 -> 0 | K16: =C16+E16+G16+I16 -> 0
A17: 12월 | C17: ='12월'!A11 -> 0 | E17: ='12월'!A13 -> 0 | G17: ='12월'!A8 -> 0 | I17: ='12월'!A15 -> 0 | J17: =B17+D17+F17+H17 -> 0 | K17: =C17+E17+G17+I17 -> 0
A18: 합계 | B18: =SUM(B6:B17) -> 0 | C18: =SUM(C6:C17) -> 0 | D18: =SUM(D6:D17) -> 0 | E18: =SUM(E6:E17) -> 0 | F18: =SUM(F6:F17) -> 0 | G18: =SUM(G6:G17) -> 0 | H18: =SUM(H6:H17) -> 0 | I18: =SUM(I6:I17) -> 0 | J18: =B18+D18+F18+H18 -> 0 | K18: =C18+E18+G18+I18 -> 0
A19: 2)매출현황
A20: 매출
A21: 월 | B21: 건설사업부 | D21: 학술사업부 | F21: 개발사업부 | H21: 외주용역 | J21: 합계 | L21: 비고
B22: 건수 | C22: 금액 | D22: 건수 | E22: 금액 | F22: 건수 | G22: 금액 | H22: 건수 | I22: 금액 | J22: 총건수 | K22: 총금액
A23: 1월 | B23: =SUM('1월'!C23:C25) -> 0 | C23: ='1월'!A25 -> 0 | D23: =SUM('1월'!C26:C27) -> 0 | E23: ='1월'!A27 -> 0 | F23: =SUM('1월'!C19:C22) -> 0 | G23: ='1월'!A22 -> 0 | H23: =SUM('1월'!C28:C29) -> 0 | I23: ='1월'!A29 -> 0 | J23: =B23+D23+F23+H23 -> 0 | K23: =C23+E23+G23+I23 -> 0
A24: 2월 | B24: =SUM('2월'!C24:C26) -> 0 | C24: ='2월'!A26 -> 0 | D24: =SUM('2월'!C27:C29) -> 0 | E24: ='2월'!A29 -> 0 | F24: =SUM('2월'!C22:C23) -> 0 | G24: ='2월'!A23 -> 0 | H24: =SUM('2월'!C30:C31) -> 0 | I24: ='2월'!A31 -> 0 | J24: =B24+D24+F24+H24 -> 0 | K24: =C24+E24+G24+I24 -> 0
A25: 3월 | B25: =SUM('3월'!C30:C38) -> 0 | C25: ='3월'!A38 -> 0 | D25: =SUM('2월'!C27:C29) -> 0 | E25: ='3월'!A41 -> 0 | F25: =SUM('3월'!C28:C29) -> 0 | G25: 0 | H25: =SUM('3월'!C42:C45) -> 0 | I25: ='3월'!A45 -> 0 | J25: =B25+D25+F25+H25 -> 0 | K25: =C25+E25+G25+I25 -> 0
A26: 4월 | B26: =SUM('4월'!C25:C33) -> 0 | C26: ='4월'!A33 -> 0 | D26: =SUM('4월'!C34:C35) -> 0 | E26: ='4월'!A35 -> 0 | F26: =SUM('4월'!C23:C24) -> 0 | G26: ='4월'!A24 -> 0 | H26: =SUM('4월'!C36:C37) -> 0 | I26: ='4월'!A37 -> 0 | J26: =B26+D26+F26+H26 -> 0 | K26: =C26+E26+G26+I26 -> 0
A27: 5월 | B27: =SUM('5월'!C24:C29) -> 0 | C27: ='5월'!A29 -> 0 | D27: =SUM('5월'!C30:C31) -> 0 | E27: ='5월'!A31 -> 0 | F27: =SUM('5월'!C22:C23) -> 0 | G27: ='5월'!A23 -> 0 | H27: =SUM('5월'!C32:C35) -> 0 | I27: ='5월'!A35 -> 0 | J27: =B27+D27+F27+H27 -> 0 | K27: =C27+E27+G27+I27 -> 0
A28: 6월 | B28: =SUM('6월'!C28:C30) -> 0 | C28: ='6월'!A30 -> 0 | D28: =SUM('6월'!C31:C32) -> 0 | E28: ='6월'!A32 -> 0 | F28: =SUM('6월'!C26:C27) -> 0 | G28: ='6월'!A27 -> 0 | H28: =SUM('6월'!C33:C36) -> 0 | I28: ='6월'!A36 -> 0 | J28: =B28+D28+F28+H28 -> 0 | K28: =C28+E28+G28+I28 -> 0
A29: 7월 | B29: =SUM('7월'!C28:C34) -> 0 | C29: ='7월'!A34 -> 0 | D29: =SUM('7월'!C35:C36) -> 0 | E29: ='7월'!A36 -> 0 | F29: =SUM('7월'!C26:C27) -> 0 | G29: ='7월'!A27 -> 0 | H29: =SUM('7월'!C37:C40) -> 0 | I29: ='7월'!A40 -> 0 | J29: =B29+D29+F29+H29 -> 0 | K29: =C29+E29+G29+I29 -> 0
A30: 8월 | B30: =SUM('8월'!C23:C27) -> 0 | C30: ='8월'!A27 -> 0 | D30: =SUM('8월'!C28:C29) -> 0 | E30: ='8월'!A29 -> 0 | F30: =SUM('8월'!C21:C22) -> 0 | G30: ='8월'!A22 -> 0 | H30: =SUM('8월'!C30:C32) -> 0 | I30: ='8월'!A32 -> 0 | J30: =B30+D30+F30+H30 -> 0 | K30: =C30+E30+G30+I30 -> 0
A31: 9월 | B31: =SUM('9월'!C33:C44) -> 0 | C31: ='9월'!A44 -> 0 | D31: =SUM('9월'!C45:C47) -> 0 | E31: ='9월'!A47 -> 0 | F31: =SUM('9월'!C30:C32) -> 0 | G31: ='9월'!A32 -> 0 | H31: =SUM('9월'!C48:C50) -> 0 | I31: ='9월'!A50 -> 0 | J31: =B31+D31+F31+H31 -> 0 | K31: =C31+E31+G31+I31 -> 0
A32: 10월 | B32: =SUM('10월'!C29:C37) -> 0 | C32: ='10월'!A37 -> 0 | D32: =SUM('10월'!C38:C39) -> 0 | E32: ='10월'!A39 -> 0 | F32: =SUM('10월'!C27:C28) -> 0 | G32: ='10월'!A28 -> 0 | H32: =SUM('10월'!C40:C41) -> 0 | I32: ='10월'!A41 -> 0 | J32: =B32+D32+F32+H32 -> 0 | K32: =C32+E32+G32+I32 -> 0
A33: 11월 | C33: ='11월'!A28 -> 0 | E33: ='11월'!A30 -> 0 | G33: ='11월'!A21 -> 0 | I33: ='11월'!A32 -> 0 | J33: =B33+D33+F33+H33 -> 0 | K33: =C33+E33+G33+I33 -> 0
A34: 12월 | C34: ='12월'!A28 -> 0 | E34: ='12월'!A30 -> 0 | G34: ='12월'!A21 -> 0 | I34: ='12월'!A32 -> 0 | J34: =B34+D34+F34+H34 -> 0 | K34: =C34+E34+G34+I34 -> 0
A35: 합계 | B35: =SUM(B23:B34) -> 0 | C35: =SUM(C23:C34) -> 0 | D35: =SUM(D23:D34) -> 0 | E35: =SUM(E23:E34) -> 0 | F35: =SUM(F23:F34) -> 0 | G35: =SUM(G23:G34) -> 0 | H35: =SUM(H23:H34) -> 0 | I35: =SUM(I23:I34) -> 0 | J35: =B35+D35+F35+H35 -> 0 | K35: =C35+E35+G35+I35 -> 0
A36: 매출/계약비율(%) | C36: =C35/C18% -> #DIV/0! | E36: =E35/E18% -> #DIV/0! | G36: =G35/G18% -> #DIV/0! | I36: =I35/I18% -> #DIV/0! | K36: =K35/K18% -> #DIV/0!
A37: 4. 2026년 총 순이익현황
A38: 월별 | B38: 총매출금액 | E38: 수금액 | G38: 경비 | H38: 매출금액대비 순이익 | J38: 수금액대비 순이익 | L38: 비고
A39: 1월 | B39: ='1월'!A33 -> 0 | E39: ='1월'!B33 -> 0 | G39: ='1월'!C33 -> 0 | H39: =B39-G39 -> 0 | J39: =E39-G39 -> 0
A40: 2월 | B40: =K24 -> 0 | E40: ='2월'!B35 -> 0 | G40: ='2월'!C35 -> 0 | H40: =B40-G40 -> 0 | J40: =E40-G40 -> 0
...
